Workbook
Name SPY_ETF_Stock_Price_History__1: Prices!$A$1:$G$3

Sheet Prices
B2: Prices | M2: Returns | X2: Statistics
A3: Date | B3: SPY | C3: VGK | D3: VWO | E3: IEF | F3: LQD | G3: TIP | H3: VNQ | I3: GLD | J3: DBC | K3: BTC | M3: SPY | N3: VGK | O3: VWO | P3: IEF | Q3: LQD | R3: TIP | S3: VNQ | T3: GLD | U3: DBC | V3: BTC | Y3: SPY | Z3: VGK | AA3: VWO | AB3: IEF | AC3: LQD | AD3: TIP | AE3: VNQ | AF3: GLD | AG3: DBC | AH3: BTC
A4: 43496 | B4: 244.838 | C4: 45.747 | D4: 37.0077 | E4: 101.081 | F4: 109.187 | G4: 104.612 | H4: 73.4013 | I4: 124.75 | J4: 15.279 | K4: 3450.66 | X4: Monthly return | Y4: =AVERAGE(M5:M87) -> 0.013353829 | Z4: =AVERAGE(N5:N87) -> 0.0084964115 | AA4: =AVERAGE(O5:O87) -> 0.0054307927 | AB4: =AVERAGE(P5:P87) -> -0.00033629338 | AC4: =AVERAGE(Q5:Q87) -> 0.00051088612 | AD4: =AVERAGE(R5:R87) -> 0.00079045933 | AE4: =AVERAGE(S5:S87) -> 0.0038919991 | AF4: =AVERAGE(T5:T87) -> 0.01496557 | ... AH4: =AVERAGE(V5:V87) -> 0.057898273
A5: 43524 | B5: 252.811 | C5: 47.1948 | D5: 36.8661 | E5: 100.544 | F5: 108.948 | G5: 104.424 | H5: 73.9095 | I5: 123.99 | J5: 15.712 | K5: 3829.95 | M5: =(B5-B4)/B4 -> 0.03256439 | N5: =(C5-C4)/C4 -> 0.031647977 | O5: =(D5-D4)/D4 -> -0.0038262308 | P5: =(E5-E4)/E4 -> -0.0053125711 | Q5: =(F5-F4)/F4 -> -0.0021889053 | R5: =(G5-G4)/G4 -> -0.001797117 | S5: =(H5-H4)/H4 -> 0.0069235831 | T5: =(I5-I4)/I4 -> -0.0060921844 | ... V5: =(K5-K4)/K4 -> 0.1099181 | X5: equiv. yearly return | Y5: =(1+Y4)^12-1 -> 0.17255535 | Z5: =(1+Z4)^12-1 -> 0.10685896 | AA5: =(1+AA4)^12-1 -> 0.067151757 | AB5: =(1+AB4)^12-1 -> -0.0040280647 | AC5: =(1+AC4)^12-1 -> 0.0061478891 | AD5: =(1+AD4)^12-1 -> 0.0095268593 | AE5: =(1+AE4)^12-1 -> 0.047716818 | AF5: =(1+AF4)^12-1 -> 0.19513158 | ... AH5: =(1+AH4)^12-1 -> 0.96483868
A6: 43555 | B6: 257.355 | C6: 47.5562 | D6: 37.7169 | E6: 103.264 | F6: 112.16 | G6: 106.514 | H6: 77.0306 | I6: 122.01 | J6: 15.653 | K6: 4101.72 | M6: =(B6-B5)/B5 -> 0.017973901 | N6: =(C6-C5)/C5 -> 0.0076576233 | O6: =(D6-D5)/D5 -> 0.023078112 | P6: =(E6-E5)/E5 -> 0.027052833 | Q6: =(F6-F5)/F5 -> 0.029481955 | R6: =(G6-G5)/G5 -> 0.020014556 | S6: =(H6-H5)/H5 -> 0.042228672 | T6: =(I6-I5)/I5 -> -0.01596903 | ... V6: =(K6-K5)/K5 -> 0.070959151 | X6: volatility of monthly returns | Y6: =_xlfn.STDEV.S(M5:M87) -> 0.047649233 | Z6: =_xlfn.STDEV.S(N5:N87) -> 0.052220983 | AA6: =_xlfn.STDEV.S(O5:O87) -> 0.046186392 | AB6: =_xlfn.STDEV.S(P5:P87) -> 0.021051838 | AC6: =_xlfn.STDEV.S(Q5:Q87) -> 0.027482967 | AD6: =_xlfn.STDEV.S(R5:R87) -> 0.017505262 | AE6: =_xlfn.STDEV.S(S5:S87) -> 0.054720964 | AF6: =_xlfn.STDEV.S(T5:T87) -> 0.041946019 | ... AH6: =_xlfn.STDEV.S(V5:V87) -> 0.1995656
A7: 43585 | B7: 267.893 | C7: 49.4197 | D7: 38.5263 | E7: 102.726 | F7: 112.657 | G7: 106.742 | H7: 76.9067 | I7: 121.2 | J7: 15.84 | K7: 5370.57 | M7: =(B7-B6)/B6 -> 0.04094733 | N7: =(C7-C6)/C6 -> 0.039185217 | O7: =(D7-D6)/D6 -> 0.021459876 | P7: =(E7-E6)/E6 -> -0.0052099473 | Q7: =(F7-F6)/F6 -> 0.0044311698 | R7: =(G7-G6)/G6 -> 0.0021405637 | S7: =(H7-H6)/H6 -> -0.0016084517 | T7: =(I7-I6)/I6 -> -0.0066388001 | ... V7: =(K7-K6)/K6 -> 0.30934584 | X7: equiv. yearly volatility | Y7: =SQRT(12)*Y6 -> 0.16506178 | Z7: =SQRT(12)*Z6 -> 0.18089879 | AA7: =SQRT(12)*AA6 -> 0.15999435 | AB7: =SQRT(12)*AB6 -> 0.072925707 | AC7: =SQRT(12)*AC6 -> 0.095203789 | AD7: =SQRT(12)*AD6 -> 0.060640006 | AE7: =SQRT(12)*AE6 -> 0.18955898 | AF7: =SQRT(12)*AF6 -> 0.14530527 | ... AH7: =SQRT(12)*AH6 -> 0.69131553
A8: 43616 | B8: 250.781 | C8: 46.6172 | D8: 36.0672 | E8: 105.853 | F8: 114.478 | G8: 108.583 | H8: 77.0129 | I8: 123.33 | J8: 14.895 | K8: 8431.7 | M8: =(B8-B7)/B7 -> -0.063876249 | N8: =(C8-C7)/C7 -> -0.056708155 | O8: =(D8-D7)/D7 -> -0.063829125 | P8: =(E8-E7)/E7 -> 0.0304402 | Q8: =(F8-F7)/F7 -> 0.016164109 | R8: =(G8-G7)/G7 -> 0.017247194 | S8: =(H8-H7)/H7 -> 0.001380894 | T8: =(I8-I7)/I7 -> 0.017574257 | ... V8: =(K8-K7)/K7 -> 0.56998233
A9: 43646 | B9: 268.246 | C9: 49.5786 | D9: 38.005 | E9: 107.109 | F9: 118.217 | G9: 109.425 | H9: 78.2132 | I9: 133.2 | J9: 15.486 | K9: 12315 | M9: =(B9-B8)/B8 -> 0.069642437 | N9: =(C9-C8)/C8 -> 0.063525909 | O9: =(D9-D8)/D8 -> 0.053727486 | P9: =(E9-E8)/E8 -> 0.011865512 | Q9: =(F9-F8)/F8 -> 0.032661297 | R9: =(G9-G8)/G8 -> 0.0077544367 | S9: =(H9-H8)/H8 -> 0.015585701 | T9: =(I9-I8)/I8 -> 0.08002919 | ... V9: =(K9-K8)/K8 -> 0.46055956
A10: 43677 | B10: 272.294 | C10: 48.2878 | D10: 37.316 | E10: 107.149 | F10: 118.505 | G10: 109.762 | H10: 79.5452 | I10: 133.21 | J10: 15.309 | K10: 10050 | M10: =(B10-B9)/B9 -> 0.015090626 | N10: =(C10-C9)/C9 -> -0.026035427 | O10: =(D10-D9)/D9 -> -0.018129194 | P10: =(E10-E9)/E9 -> 0.00037345134 | Q10: =(F10-F9)/F9 -> 0.0024361978 | R10: =(G10-G9)/G9 -> 0.003079735 | S10: =(H10-H9)/H9 -> 0.017030373 | T10: =(I10-I9)/I9 -> 7.5075075e-05 | ... V10: =(K10-K9)/K9 -> -0.18392205 | X10: Covariances of monthly returns | Y10: SPY | Z10: VGK | AA10: VWO | AB10: IEF | AC10: LQD | AD10: TIP | AE10: VNQ | AF10: GLD | AG10: DBC | AH10: BTC | AJ10: Sylvester's criterion
A11: 43708 | B11: 267.751 | C11: 47.4932 | D11: 36.1009 | E11: 111.403 | F11: 123.11 | G11: 112.327 | H11: 82.5247 | I11: 143.75 | J11: 14.6 | K11: 9578.54 | M11: =(B11-B10)/B10 -> -0.016684172 | N11: =(C11-C10)/C10 -> -0.016455502 | O11: =(D11-D10)/D10 -> -0.03256244 | P11: =(E11-E10)/E10 -> 0.039701724 | Q11: =(F11-F10)/F10 -> 0.03885912 | R11: =(G11-G10)/G10 -> 0.023368743 | S11: =(H11-H10)/H10 -> 0.037456691 | T11: =(I11-I10)/I10 -> 0.079123189 | ... V11: =(K11-K10)/K10 -> -0.046911443 | X11: SPY | Y11: =_xlfn.COVARIANCE.S($M$5:$M$87,M$5:M$87) -> 0.0022704494 | Z11: =_xlfn.COVARIANCE.S($M$5:$M$87,N$5:N$87) -> 0.0020767105 | AA11: =_xlfn.COVARIANCE.S($M$5:$M$87,O$5:O$87) -> 0.0015167281 | AB11: =_xlfn.COVARIANCE.S($M$5:$M$87,P$5:P$87) -> 0.00024655077 | AC11: =_xlfn.COVARIANCE.S($M$5:$M$87,Q$5:Q$87) -> 0.0008681289 | AD11: =_xlfn.COVARIANCE.S($M$5:$M$87,R$5:R$87) -> 0.00048962367 | AE11: =_xlfn.COVARIANCE.S($M$5:$M$87,S$5:S$87) -> 0.0021278402 | AF11: =_xlfn.COVARIANCE.S($M$5:$M$87,T$5:T$87) -> 0.0003152741 | ... AH11: =_xlfn.COVARIANCE.S($M$5:$M$87,V$5:V$87) -> 0.0043833924 | AJ11: =MDETERM($Y$11:Y11) -> 0.0022704494
A12: 43738 | B12: 272.947 | C12: 48.7016 | D12: 36.4324 | E12: 110.067 | F12: 122.185 | G12: 111.089 | H12: 84.1123 | I12: 138.87 | J12: 14.807 | K12: 8271.3 | M12: =(B12-B11)/B11 -> 0.01940609 | N12: =(C12-C11)/C11 -> 0.025443642 | O12: =(D12-D11)/D11 -> 0.0091825966 | P12: =(E12-E11)/E11 -> -0.011992496 | Q12: =(F12-F11)/F11 -> -0.0075136057 | R12: =(G12-G11)/G11 -> -0.011021393 | S12: =(H12-H11)/H11 -> 0.019237877 | T12: =(I12-I11)/I11 -> -0.033947826 | ... V12: =(K12-K11)/K11 -> -0.13647591 | X12: VGK | Y12: {=TRANSPOSE(Z11:AH11)} -> 0.0020767105 | Z12: =_xlfn.COVARIANCE.S($N$5:$N$87,N$5:N$87) -> 0.002727031 | AA12: =_xlfn.COVARIANCE.S($N$5:$N$87,O$5:O$87) -> 0.0018617817 | AB12: =_xlfn.COVARIANCE.S($N$5:$N$87,P$5:P$87) -> 0.00032035324 | AC12: =_xlfn.COVARIANCE.S($N$5:$N$87,Q$5:Q$87) -> 0.00098015515 | AD12: =_xlfn.COVARIANCE.S($N$5:$N$87,R$5:R$87) -> 0.00052070188 | AE12: =_xlfn.COVARIANCE.S($N$5:$N$87,S$5:S$87) -> 0.0022509924 | AF12: =_xlfn.COVARIANCE.S($N$5:$N$87,T$5:T$87) -> 0.0006167478 | AG12: =_xlfn.COVARIANCE.S($N$5:$N$87,U$5:U$87) -> 0.0012565362 | AH12: =_xlfn.COVARIANCE.S($N$5:$N$87,V$5:V$87) -> 0.0034866626 | AK12: =MDETERM($Y$11:Z12) -> 1.8788593e-06
A13: 43769 | B13: 278.985 | C13: 50.5728 | D13: 37.8692 | E13: 110.277 | F13: 122.741 | G13: 111.059 | H13: 85.0599 | I13: 142.43 | J13: 15.092 | K13: 9132.42 | M13: =(B13-B12)/B12 -> 0.022121511 | N13: =(C13-C12)/C12 -> 0.038421736 | O13: =(D13-D12)/D12 -> 0.039437424 | P13: =(E13-E12)/E12 -> 0.0019079288 | Q13: =(F13-F12)/F12 -> 0.0045504767 | R13: =(G13-G12)/G12 -> -0.00027005374 | S13: =(H13-H12)/H12 -> 0.011265891 | T13: =(I13-I12)/I12 -> 0.025635486 | ... V13: =(K13-K12)/K12 -> 0.10410939 | X13: VWO | Y13: 0.0015167281 | Z13: {=TRANSPOSE(AA12:AH12)} -> 0.0018617817 | AA13: =_xlfn.COVARIANCE.S($O$4:$O$87,O$4:O$87) -> 0.0021331828 | AB13: =_xlfn.COVARIANCE.S($O$4:$O$87,P$4:P$87) -> 0.00021122084 | AC13: =_xlfn.COVARIANCE.S($O$4:$O$87,Q$4:Q$87) -> 0.00081478014 | AD13: =_xlfn.COVARIANCE.S($O$4:$O$87,R$4:R$87) -> 0.00036327617 | AE13: =_xlfn.COVARIANCE.S($O$4:$O$87,S$4:S$87) -> 0.0015654872 | AF13: =_xlfn.COVARIANCE.S($O$4:$O$87,T$4:T$87) -> 0.00066915255 | AG13: =_xlfn.COVARIANCE.S($O$4:$O$87,U$4:U$87) -> 0.0011266468 | AH13: =_xlfn.COVARIANCE.S($O$4:$O$87,V$4:V$87) -> 0.0023628252 | AL13: =MDETERM($Y$11:AA13) -> 1.5931104e-09
A14: 43799 | B14: 289.074 | C14: 51.2279 | D14: 38.0589 | E14: 109.519 | F14: 123.319 | G14: 111.376 | H14: 83.9501 | I14: 137.86 | J14: 15.072 | K14: 7757.95 | M14: =(B14-B13)/B13 -> 0.036163235 | N14: =(C14-C13)/C13 -> 0.012953604 | O14: =(D14-D13)/D13 -> 0.005009348 | P14: =(E14-E13)/E13 -> -0.0068736001 | Q14: =(F14-F13)/F13 -> 0.0047091029 | R14: =(G14-G13)/G13 -> 0.0028543387 | S14: =(H14-H13)/H13 -> -0.013047276 | T14: =(I14-I13)/I13 -> -0.032085937 | ... V14: =(K14-K13)/K13 -> -0.15050447 | X14: IEF | Y14: 0.00024655077 | Z14: 0.00032035324 | AA14: {=TRANSPOSE(AB13:AH13)} -> 0.00021122084 | AB14: =_xlfn.COVARIANCE.S($P$4:$P$87,P$4:P$87) -> 0.00044317989 | AC14: =_xlfn.COVARIANCE.S($P$4:$P$87,Q$4:Q$87) -> 0.00045320247 | AD14: =_xlfn.COVARIANCE.S($P$4:$P$87,R$4:R$87) -> 0.00028385848 | AE14: =_xlfn.COVARIANCE.S($P$4:$P$87,S$4:S$87) -> 0.00045466286 | AF14: =_xlfn.COVARIANCE.S($P$4:$P$87,T$4:T$87) -> 0.00032458125 | AG14: =_xlfn.COVARIANCE.S($P$4:$P$87,U$4:U$87) -> -0.00029937042 | AH14: =_xlfn.COVARIANCE.S($P$4:$P$87,V$4:V$87) -> 0.00049748579 | AM14: =MDETERM($Y$11:AB14) -> 6.459494e-13
A15: 43830 | B15: 297.478 | C15: 53.5372 | D15: 40.7513 | E15: 108.494 | F15: 123.985 | G15: 111.762 | H15: 84.596 | I15: 142.9 | J15: 15.95 | K15: 7194.24 | M15: =(B15-B14)/B14 -> 0.029072141 | N15: =(C15-C14)/C14 -> 0.045078951 | O15: =(D15-D14)/D14 -> 0.07074298 | P15: =(E15-E14)/E14 -> -0.0093591066 | Q15: =(F15-F14)/F14 -> 0.0054006276 | R15: =(G15-G14)/G14 -> 0.0034657377 | S15: =(H15-H14)/H14 -> 0.0076938562 | T15: =(I15-I14)/I14 -> 0.036558828 | ... V15: =(K15-K14)/K14 -> -0.072662237 | X15: LQD | Y15: 0.0008681289 | Z15: 0.00098015515 | AA15: 0.00081478014 | AB15: {=TRANSPOSE(AC14:AH14)} -> 0.00045320247 | AC15: =_xlfn.COVARIANCE.S($Q$4:$Q$87,Q$4:Q$87) -> 0.00075531345 | AD15: =_xlfn.COVARIANCE.S($Q$4:$Q$87,R$4:R$87) -> 0.00039641232 | AE15: =_xlfn.COVARIANCE.S($Q$4:$Q$87,S$4:S$87) -> 0.0011004556 | AF15: =_xlfn.COVARIANCE.S($Q$4:$Q$87,T$4:T$87) -> 0.00043838635 | AG15: =_xlfn.COVARIANCE.S($Q$4:$Q$87,U$4:U$87) -> 0.00011272438 | AH15: =_xlfn.COVARIANCE.S($Q$4:$Q$87,V$4:V$87) -> 0.0017126919 | AN15: =MDETERM($Y$11:AC15) -> 5.1080238e-17
A16: 43861 | B16: 297.351 | C16: 51.885 | D16: 38.4975 | E16: 112.269 | F16: 127.008 | G16: 114.159 | H16: 85.634 | I16: 149.33 | J16: 14.58 | K16: 9310.99 | M16: =(B16-B15)/B15 -> -0.00042692233 | N16: =(C16-C15)/C15 -> -0.030860785 | O16: =(D16-D15)/D15 -> -0.055306211 | P16: =(E16-E15)/E15 -> 0.034794551 | Q16: =(F16-F15)/F15 -> 0.024381982 | R16: =(G16-G15)/G15 -> 0.021447361 | S16: =(H16-H15)/H15 -> 0.012270084 | T16: =(I16-I15)/I15 -> 0.044996501 | ... V16: =(K16-K15)/K15 -> 0.29422844 | X16: TIP | Y16: 0.00048962367 | Z16: 0.00052070188 | AA16: 0.00036327617 | AB16: 0.00028385848 | AC16: {=TRANSPOSE(AD15:AH15)} -> 0.00039641232 | AD16: =_xlfn.COVARIANCE.S($R$4:$R$87,R$4:R$87) -> 0.00030643419 | AE16: =_xlfn.COVARIANCE.S($R$4:$R$87,S$4:S$87) -> 0.00064094753 | AF16: =_xlfn.COVARIANCE.S($R$4:$R$87,T$4:T$87) -> 0.00030799929 | AG16: =_xlfn.COVARIANCE.S($R$4:$R$87,U$4:U$87) -> 7.3273513e-05 | AH16: =_xlfn.COVARIANCE.S($R$4:$R$87,V$4:V$87) -> 0.0012091978 | AO16: =MDETERM($Y$11:AD16) -> 3.6643133e-21
A17: 43890 | B17: 273.828 | C17: 47.7548 | D17: 37.131 | E17: 115.586 | F17: 128.411 | G17: 115.198 | H17: 79.6179 | I17: 148.38 | J17: 13.61 | K17: 8620.69 | M17: =(B17-B16)/B16 -> -0.079108528 | N17: =(C17-C16)/C16 -> -0.079602968 | O17: =(D17-D16)/D16 -> -0.035495811 | P17: =(E17-E16)/E16 -> 0.02954511 | Q17: =(F17-F16)/F16 -> 0.011046548 | R17: =(G17-G16)/G16 -> 0.0091013411 | S17: =(H17-H16)/H16 -> -0.070253638 | T17: =(I17-I16)/I16 -> -0.0063617491 | ... V17: =(K17-K16)/K16 -> -0.074138196 | X17: VNQ | Y17: 0.0021278402 | Z17: 0.0022509924 | AA17: 0.0015654872 | AB17: 0.00045466286 | AC17: 0.0011004556 | AD17: {=TRANSPOSE(AE16:AH16)} -> 0.00064094753 | AE17: =_xlfn.COVARIANCE.S($S$4:$S$87,S$4:S$87) -> 0.0029943839 | AF17: =_xlfn.COVARIANCE.S($S$4:$S$87,T$4:T$87) -> 0.00049490851 | AG17: =_xlfn.COVARIANCE.S($S$4:$S$87,U$4:U$87) -> 0.00096027881 | AH17: =_xlfn.COVARIANCE.S($S$4:$S$87,V$4:V$87) -> 0.0043492964 | AP17: =MDETERM($Y$11:AE17) -> 2.6255843e-24
A18: 43921 | B18: 239.64 | C18: 39.8039 | D18: 30.8039 | E18: 119.909 | F18: 119.977 | G18: 113.188 | H18: 64.1776 | I18: 148.05 | J18: 11.25 | K18: 6459.95 | M18: =(B18-B17)/B17 -> -0.1248521 | N18: =(C18-C17)/C17 -> -0.16649426 | O18: =(D18-D17)/D17 -> -0.1703994 | P18: =(E18-E17)/E17 -> 0.037400723 | Q18: =(F18-F17)/F17 -> -0.065679731 | R18: =(G18-G17)/G17 -> -0.01744822 | S18: =(H18-H17)/H17 -> -0.19393001 | T18: =(I18-I17)/I17 -> -0.0022240194 | ... V18: =(K18-K17)/K17 -> -0.25064583 | X18: GLD | Y18: 0.0003152741 | Z18: 0.0006167478 | AA18: 0.00066915255 | AB18: 0.00032458125 | AC18: 0.00043838635 | AD18: 0.00030799929 | AE18: {=TRANSPOSE(AF17:AH17)} -> 0.00049490851 | AF18: =_xlfn.COVARIANCE.S($T$4:$T$87,T$4:T$87) -> 0.0017594685 | AG18: =_xlfn.COVARIANCE.S($T$4:$T$87,U$4:U$87) -> 7.3037439e-05 | AH18: =_xlfn.COVARIANCE.S($T$4:$T$87,V$4:V$87) -> 0.001105891 | AQ18: =MDETERM($Y$11:AF18) -> 3.2937397e-27
A19: 43951 | B19: 270.067 | C19: 42.3688 | D19: 33.2062 | E19: 120.218 | F19: 125.785 | G19: 116.624 | H19: 69.9292 | I19: 158.8 | J19: 10.9 | K19: 8764.24 | M19: =(B19-B18)/B18 -> 0.12696962 | N19: =(C19-C18)/C18 -> 0.064438409 | O19: =(D19-D18)/D18 -> 0.077986878 | P19: =(E19-E18)/E18 -> 0.0025769542 | Q19: =(F19-F18)/F18 -> 0.048409278 | R19: =(G19-G18)/G18 -> 0.030356575 | S19: =(H19-H18)/H18 -> 0.089620054 | T19: =(I19-I18)/I18 -> 0.072610605 | ... V19: =(K19-K18)/K18 -> 0.356704 | X19: DBC | Y19: 0.00097690527 | Z19: 0.0012565362 | AA19: 0.0011266468 | AB19: -0.00029937042 | AC19: 0.00011272438 | AD19: 7.3273513e-05 | AE19: 0.00096027881 | AF19: {=TRANSPOSE(AG18:AH18)} -> 7.3037439e-05 | AG19: =_xlfn.COVARIANCE.S($U$4:$U$87,U$4:U$87) -> 0.0024314902 | AH19: =_xlfn.COVARIANCE.S($U$4:$U$87,V$4:V$87) -> 0.0010456425 | AR19: =MDETERM($Y$11:AG19) -> 3.886177e-30
A20: 43982 | B20: 282.93 | C20: 44.8428 | D20: 34.299 | E20: 120.487 | F20: 128.58 | G20: 117.07 | H20: 71.1413 | I20: 162.91 | J20: 11.78 | K20: 9398.5 | M20: =(B20-B19)/B19 -> 0.047628922 | N20: =(C20-C19)/C19 -> 0.058392024 | O20: =(D20-D19)/D19 -> 0.032909517 | P20: =(E20-E19)/E19 -> 0.0022376017 | Q20: =(F20-F19)/F19 -> 0.022220456 | R20: =(G20-G19)/G19 -> 0.0038242557 | S20: =(H20-H19)/H19 -> 0.017333246 | T20: =(I20-I19)/I19 -> 0.025881612 | ... V20: =(K20-K19)/K19 -> 0.072369082 | X20: BTC | Y20: 0.0043833924 | Z20: 0.0034866626 | AA20: 0.0023628252 | AB20: 0.00049748579 | AC20: 0.0017126919 | AD20: 0.0012091978 | AE20: 0.0043492964 | AF20: 0.001105891 | AG20: =AH19 -> 0.0010456425 | AH20: =_xlfn.COVARIANCE.S($V$4:$V$87,V$4:V$87) -> 0.03982643 | AS20: =MDETERM($Y$11:AH20) -> 1.1358429e-31
A21: 44012 | B21: 287.954 | C21: 46.6054 | D21: 36.5211 | E21: 120.537 | F21: 131.294 | G21: 118.249 | H21: 72.8685 | I21: 167.37 | J21: 12.31 | K21: 9165.9 | M21: =(B21-B20)/B20 -> 0.017757042 | N21: =(C21-C20)/C20 -> 0.039306199 | O21: =(D21-D20)/D20 -> 0.064786145 | P21: =(E21-E20)/E20 -> 0.00041498253 | Q21: =(F21-F20)/F20 -> 0.021107482 | R21: =(G21-G20)/G20 -> 0.010070898 | S21: =(H21-H20)/H20 -> 0.024278443 | T21: =(I21-I20)/I20 -> 0.027377079 | ... V21: =(K21-K20)/K20 -> -0.02474863
A22: 44043 | B22: 304.904 | C22: 48.3081 | D22: 39.6557 | E22: 121.573 | F22: 135.362 | G22: 120.982 | H22: 75.5216 | I22: 185.43 | J22: 12.94 | K22: 11328 | M22: =(B22-B21)/B21 -> 0.058863568 | N22: =(C22-C21)/C21 -> 0.036534393 | O22: =(D22-D21)/D21 -> 0.085829835 | P22: =(E22-E21)/E21 -> 0.0085948713 | Q22: =(F22-F21)/F21 -> 0.030983899 | R22: =(G22-G21)/G21 -> 0.023112246 | S22: =(H22-H21)/H21 -> 0.036409422 | T22: =(I22-I21)/I21 -> 0.10790464 | ... V22: =(K22-K21)/K21 -> 0.23588518
A23: 44074 | B23: 326.189 | C23: 50.3926 | D23: 40.7446 | E23: 120.387 | F23: 132.965 | G23: 122.071 | H23: 75.8549 | I23: 184.83 | J23: 13.54 | K23: 11640 | M23: =(B23-B22)/B22 -> 0.069808858 | N23: =(C23-C22)/C22 -> 0.043150114 | O23: =(D23-D22)/D22 -> 0.027458852 | P23: =(E23-E22)/E22 -> -0.0097554556 | Q23: =(F23-F22)/F22 -> -0.017708072 | R23: =(G23-G22)/G22 -> 0.009001339 | S23: =(H23-H22)/H22 -> 0.0044133069 | T23: =(I23-I22)/I22 -> -0.0032357224 | ... V23: =(K23-K22)/K22 -> 0.027542373
A24: 44104 | B24: 313.977 | C24: 48.8228 | D24: 40.257 | E24: 120.697 | F24: 132.091 | G24: 121.596 | H24: 73.8358 | I24: 177.12 | J24: 13.06 | K24: 10709 | M24: =(B24-B23)/B23 -> -0.037438418 | N24: =(C24-C23)/C23 -> -0.031151399 | O24: =(D24-D23)/D23 -> -0.01196723 | P24: =(E24-E23)/E23 -> 0.0025750289 | Q24: =(F24-F23)/F23 -> -0.0065731583 | R24: =(G24-G23)/G23 -> -0.0038911781 | S24: =(H24-H23)/H23 -> -0.026617924 | T24: =(I24-I23)/I23 -> -0.041714007 | ... V24: =(K24-K23)/K23 -> -0.079982818
A25: 44135 | B25: 306.149 | C25: 46.1781 | D25: 40.7869 | E25: 119.042 | F25: 131.414 | G25: 120.784 | H25: 71.619 | I25: 176.2 | J25: 12.65 | K25: 13637 | M25: =(B25-B24)/B24 -> -0.024931763 | N25: =(C25-C24)/C24 -> -0.054169363 | O25: =(D25-D24)/D24 -> 0.013162928 | P25: =(E25-E24)/E24 -> -0.013712023 | Q25: =(F25-F24)/F24 -> -0.0051252546 | R25: =(G25-G24)/G24 -> -0.0066778512 | S25: =(H25-H24)/H24 -> -0.030023376 | T25: =(I25-I24)/I24 -> -0.0051942186 | ... V25: =(K25-K24)/K24 -> 0.27341488 | X25: Correlations | Y25: SPY | Z25: VGK | AA25: VWO | AB25: IEF | AC25: LQD | AD25: TIP | AE25: VNQ | AF25: GLD | AG25: DBC | AH25: BTC | AM25: Fama/French 3 Factors (Monthly)
A26: 44165 | B26: 339.437 | C26: 53.7484 | D26: 44.2791 | E26: 119.372 | F26: 136.078 | G26: 121.932 | H26: 78.5484 | I26: 166.67 | J26: 13.94 | K26: 19484 | M26: =(B26-B25)/B25 -> 0.10873137 | N26: =(C26-C25)/C25 -> 0.16393702 | O26: =(D26-D25)/D25 -> 0.085620628 | P26: =(E26-E25)/E25 -> 0.0027721308 | Q26: =(F26-F25)/F25 -> 0.035490891 | R26: =(G26-G25)/G25 -> 0.0095045701 | S26: =(H26-H25)/H25 -> 0.096753655 | T26: =(I26-I25)/I25 -> -0.054086266 | ... V26: =(K26-K25)/K25 -> 0.42875999 | X26: SPY | Y26: =CORREL($M$4:$M$87,M$4:M$87) -> 1 | Z26: =CORREL($M$4:$M$87,N$4:N$87) -> 0.83459353 | AA26: =CORREL($M$4:$M$87,O$4:O$87) -> 0.68918815 | AB26: =CORREL($M$4:$M$87,P$4:P$87) -> 0.24578786 | AC26: =CORREL($M$4:$M$87,Q$4:Q$87) -> 0.66292545 | AD26: =CORREL($M$4:$M$87,R$4:R$87) -> 0.58699971 | AE26: =CORREL($M$4:$M$87,S$4:S$87) -> 0.81607365 | AF26: =CORREL($M$4:$M$87,T$4:T$87) -> 0.15773993 | ... AH26: =CORREL($M$4:$M$87,V$4:V$87) -> 0.46096585 | AL26: Date | AM26: RF | AN26: Average Monthly return | AO26: Annualized Return
A27: 44196 | B27: 352.023 | C27: 56.4491 | D27: 46.9339 | E27: 119.003 | F27: 136.009 | G27: 123.121 | H27: 80.6993 | I27: 178.36 | J27: 14.7 | K27: 29152 | M27: =(B27-B26)/B26 -> 0.037079046 | N27: =(C27-C26)/C26 -> 0.050247077 | O27: =(D27-D26)/D26 -> 0.059956052 | P27: =(E27-E26)/E26 -> -0.0030911772 | Q27: =(F27-F26)/F26 -> -0.00050706213 | R27: =(G27-G26)/G26 -> 0.0097513368 | S27: =(H27-H26)/H26 -> 0.027383117 | T27: =(I27-I26)/I26 -> 0.070138597 | ... V27: =(K27-K26)/K26 -> 0.49620201 | X27: VGK | Z27: =CORREL($N$4:$N$87,N$4:N$87) -> 1 | AA27: =CORREL($N$4:$N$87,O$4:O$87) -> 0.77191535 | AB27: =CORREL($N$4:$N$87,P$4:P$87) -> 0.29140302 | AC27: =CORREL($N$4:$N$87,Q$4:Q$87) -> 0.6829457 | AD27: =CORREL($N$4:$N$87,R$4:R$87) -> 0.56960724 | AE27: =CORREL($N$4:$N$87,S$4:S$87) -> 0.78772612 | AF27: =CORREL($N$4:$N$87,T$4:T$87) -> 0.28156056 | AG27: =CORREL($N$4:$N$87,U$4:U$87) -> 0.48797064 | AH27: =CORREL($N$4:$N$87,V$4:V$87) -> 0.33456399 | AL27: 43496 | AM27: 0.21 | AN27: =AVERAGE(AM27:AM108)/100 -> 0.0021049383 | AO27: =((1+AN27)^(12))-1 -> 0.025553751
A28: 44227 | B28: 348.434 | C28: 55.9434 | D28: 48.4053 | E28: 117.698 | F28: 133.532 | G28: 123.447 | H28: 80.7258 | I28: 172.61 | J28: 15.19 | K28: 34569 | M28: =(B28-B27)/B27 -> -0.010195357 | N28: =(C28-C27)/C27 -> -0.0089585131 | O28: =(D28-D27)/D27 -> 0.031350474 | P28: =(E28-E27)/E27 -> -0.01096611 | Q28: =(F28-F27)/F27 -> -0.01821203 | R28: =(G28-G27)/G27 -> 0.0026478018 | S28: =(H28-H27)/H27 -> 0.00032837955 | T28: =(I28-I27)/I27 -> -0.03223817 | ... V28: =(K28-K27)/K27 -> 0.18581915 | X28: VWO | AA28: =CORREL($O$4:$O$87,O$4:O$87) -> 1 | AB28: =CORREL($O$4:$O$87,P$4:P$87) -> 0.21723646 | AC28: =CORREL($O$4:$O$87,Q$4:Q$87) -> 0.64189323 | AD28: =CORREL($O$4:$O$87,R$4:R$87) -> 0.44931846 | AE28: =CORREL($O$4:$O$87,S$4:S$87) -> 0.61941506 | AF28: =CORREL($O$4:$O$87,T$4:T$87) -> 0.34539843 | AG28: =CORREL($O$4:$O$87,U$4:U$87) -> 0.49469495 | AH28: =CORREL($O$4:$O$87,V$4:V$87) -> 0.25634914 | AL28: 43524 | AM28: 0.18
A29: 44255 | B29: 358.13 | C29: 57.3853 | D29: 49.1647 | E29: 114.829 | F29: 130.24 | G29: 121.388 | H29: 83.491 | I29: 161.81 | J29: 16.73 | K29: 46234 | M29: =(B29-B28)/B28 -> 0.027827365 | N29: =(C29-C28)/C28 -> 0.025774265 | O29: =(D29-D28)/D28 -> 0.015688365 | P29: =(E29-E28)/E28 -> -0.024375945 | Q29: =(F29-F28)/F28 -> -0.024653267 | R29: =(G29-G28)/G28 -> -0.016679223 | S29: =(H29-H28)/H28 -> 0.034254229 | T29: =(I29-I28)/I28 -> -0.062568797 | ... V29: =(K29-K28)/K28 -> 0.33744106 | X29: IEF | AB29: =CORREL($P$4:$P$87,P$4:P$87) -> 1 | AC29: =CORREL($P$4:$P$87,Q$4:Q$87) -> 0.78331896 | AD29: =CORREL($P$4:$P$87,R$4:R$87) -> 0.77027045 | AE29: =CORREL($P$4:$P$87,S$4:S$87) -> 0.39468054 | AF29: =CORREL($P$4:$P$87,T$4:T$87) -> 0.3675722 | AG29: =CORREL($P$4:$P$87,U$4:U$87) -> -0.2883916 | AH29: =CORREL($P$4:$P$87,V$4:V$87) -> 0.11841452 | AL29: 43555 | AM29: 0.19
A30: 44286 | B30: 374.391 | C30: 59.2894 | D30: 48.8148 | E30: 112.02 | F30: 128.062 | G30: 121.061 | H30: 87.7957 | I30: 159.96 | J30: 16.61 | K30: 58962 | M30: =(B30-B29)/B29 -> 0.0454053 | N30: =(C30-C29)/C29 -> 0.033180971 | O30: =(D30-D29)/D29 -> -0.0071168948 | P30: =(E30-E29)/E29 -> -0.024462462 | Q30: =(F30-F29)/F29 -> -0.016722973 | R30: =(G30-G29)/G29 -> -0.0026938412 | S30: =(H30-H29)/H29 -> 0.051558851 | T30: =(I30-I29)/I29 -> -0.011433162 | ... V30: =(K30-K29)/K29 -> 0.27529524 | X30: LQD | AC30: =CORREL($Q$4:$Q$87,Q$4:Q$87) -> 1 | AD30: =CORREL($Q$4:$Q$87,R$4:R$87) -> 0.82397669 | AE30: =CORREL($Q$4:$Q$87,S$4:S$87) -> 0.73173725 | AF30: =CORREL($Q$4:$Q$87,T$4:T$87) -> 0.38027928 | AG30: =CORREL($Q$4:$Q$87,U$4:U$87) -> 0.083179825 | AH30: =CORREL($Q$4:$Q$87,V$4:V$87) -> 0.31226977 | AL30: 43585 | AM30: 0.21
A31: 44316 | B31: 394.202 | C31: 62.122 | D31: 49.6879 | E31: 113.146 | F31: 129.385 | G31: 122.804 | H31: 94.6974 | I31: 165.66 | J31: 17.91 | K31: 57081 | M31: =(B31-B30)/B30 -> 0.052915268 | N31: =(C31-C30)/C30 -> 0.047775825 | O31: =(D31-D30)/D30 -> 0.017885969 | P31: =(E31-E30)/E30 -> 0.010051776 | Q31: =(F31-F30)/F30 -> 0.010330933 | R31: =(G31-G30)/G30 -> 0.0143977 | S31: =(H31-H30)/H30 -> 0.078610911 | T31: =(I31-I30)/I30 -> 0.035633908 | ... V31: =(K31-K30)/K30 -> -0.031901903 | X31: TIP | AD31: =CORREL($R$4:$R$87,R$4:R$87) -> 1 | AE31: =CORREL($R$4:$R$87,S$4:S$87) -> 0.66911403 | AF31: =CORREL($R$4:$R$87,T$4:T$87) -> 0.41945981 | AG31: =CORREL($R$4:$R$87,U$4:U$87) -> 0.084887187 | AH31: =CORREL($R$4:$R$87,V$4:V$87) -> 0.34613304 | AL31: 43616 | AM31: 0.21
A32: 44347 | B32: 396.787 | C32: 64.8886 | D32: 50.5301 | E32: 113.554 | F32: 129.932 | G32: 123.537 | H32: 95.4622 | I32: 178.38 | J32: 18.6 | K32: 36885 | M32: =(B32-B31)/B31 -> 0.0065575517 | N32: =(C32-C31)/C31 -> 0.044534947 | O32: =(D32-D31)/D31 -> 0.016949801 | P32: =(E32-E31)/E31 -> 0.0036059604 | Q32: =(F32-F31)/F31 -> 0.0042276925 | R32: =(G32-G31)/G31 -> 0.0059688609 | S32: =(H32-H31)/H31 -> 0.0080762513 | T32: =(I32-I31)/I31 -> 0.076783774 | ... V32: =(K32-K31)/K31 -> -0.353813 | X32: VNQ | AE32: =CORREL($S$4:$S$87,S$4:S$87) -> 1 | AF32: =CORREL($S$4:$S$87,T$4:T$87) -> 0.21561573 | AG32: =CORREL($S$4:$S$87,U$4:U$87) -> 0.35588309 | AH32: =CORREL($S$4:$S$87,V$4:V$87) -> 0.39827182 | AL32: 43646 | AM32: 0.18
A33: 44377 | B33: 405.687 | C33: 63.9971 | D33: 51.2017 | E33: 114.63 | F33: 132.557 | G33: 123.774 | H33: 97.9778 | I33: 165.63 | J33: 19.25 | K33: 34796 | M33: =(B33-B32)/B32 -> 0.02243017 | N33: =(C33-C32)/C32 -> -0.013738931 | O33: =(D33-D32)/D32 -> 0.013291088 | P33: =(E33-E32)/E32 -> 0.009475668 | Q33: =(F33-F32)/F32 -> 0.020202875 | R33: =(G33-G32)/G32 -> 0.0019184536 | S33: =(H33-H32)/H32 -> 0.026351792 | T33: =(I33-I32)/I32 -> -0.071476623 | ... V33: =(K33-K32)/K32 -> -0.056635489 | X33: GLD | AF33: =CORREL($T$4:$T$87,T$4:T$87) -> 1 | AG33: =CORREL($T$4:$T$87,U$4:U$87) -> 0.035311692 | AH33: =CORREL($T$4:$T$87,V$4:V$87) -> 0.13211006 | AL33: 43677 | AM33: 0.19
A34: 44408 | B34: 415.592 | C34: 65.188 | D34: 48.1847 | E34: 116.921 | F34: 134.428 | G34: 127.092 | H34: 102.313 | I34: 169.82 | J34: 19.5 | K34: 39920 | M34: =(B34-B33)/B33 -> 0.024415374 | N34: =(C34-C33)/C33 -> 0.018608656 | O34: =(D34-D33)/D33 -> -0.058923825 | P34: =(E34-E33)/E33 -> 0.019986042 | Q34: =(F34-F33)/F33 -> 0.014114683 | R34: =(G34-G33)/G33 -> 0.026806922 | S34: =(H34-H33)/H33 -> 0.044246758 | T34: =(I34-I33)/I33 -> 0.02529735 | ... V34: =(K34-K33)/K33 -> 0.14725831 | X34: DBC | AG34: =CORREL($U$4:$U$87,U$4:U$87) -> 1 | AH34: =CORREL($U$4:$U$87,V$4:V$87) -> 0.10625791 | AL34: 43708 | AM34: 0.16
A35: 44439 | B35: 427.968 | C35: 66.3674 | D35: 49.2408 | E35: 116.383 | F35: 133.741 | G35: 126.121 | H35: 104.525 | I35: 169.69 | J35: 19.18 | K35: 46979 | M35: =(B35-B34)/B34 -> 0.029779207 | N35: =(C35-C34)/C34 -> 0.018092287 | O35: =(D35-D34)/D34 -> 0.021917746 | P35: =(E35-E34)/E34 -> -0.0046013975 | Q35: =(F35-F34)/F34 -> -0.0051105424 | R35: =(G35-G34)/G34 -> -0.0076401347 | S35: =(H35-H34)/H34 -> 0.021619931 | T35: =(I35-I34)/I34 -> -0.00076551643 | ... V35: =(K35-K34)/K34 -> 0.17682866 | X35: BTC | AH35: =CORREL($V$4:$V$87,V$4:V$87) -> 1 | AL35: 43738 | AM35: 0.18
A36: 44469 | B36: 408.012 | C36: 62.7877 | D36: 47.5824 | E36: 114.44 | F36: 131.494 | G36: 124.279 | H36: 98.5774 | I36: 164.22 | J36: 20.18 | K36: 43752 | M36: =(B36-B35)/B35 -> -0.046629655 | N36: =(C36-C35)/C35 -> -0.053937626 | O36: =(D36-D35)/D35 -> -0.033679388 | P36: =(E36-E35)/E35 -> -0.016694878 | Q36: =(F36-F35)/F35 -> -0.016801131 | R36: =(G36-G35)/G35 -> -0.014605022 | S36: =(H36-H35)/H35 -> -0.05690122 | T36: =(I36-I35)/I35 -> -0.032235253 | ... V36: =(K36-K35)/K35 -> -0.068690266 | AL36: 43769 | AM36: 0.15
A37: 44500 | B37: 436.649 | C37: 65.9458 | D37: 48.2 | E37: 113.942 | F37: 132.189 | G37: 125.656 | H37: 105.616 | I37: 166.65 | J37: 21.35 | K37: 62629 | M37: =(B37-B36)/B36 -> 0.070186661 | N37: =(C37-C36)/C36 -> 0.050298068 | O37: =(D37-D36)/D36 -> 0.012979589 | P37: =(E37-E36)/E36 -> -0.0043516253 | Q37: =(F37-F36)/F36 -> 0.0052854123 | R37: =(G37-G36)/G36 -> 0.011079909 | S37: =(H37-H36)/H36 -> 0.071401761 | T37: =(I37-I36)/I36 -> 0.014797223 | ... V37: =(K37-K36)/K36 -> 0.43145456 | AL37: 43799 | AM37: 0.12
A38: 44530 | B38: 433.135 | C38: 62.7209 | D38: 46.8028 | E38: 115.098 | F38: 131.782 | G38: 126.616 | H38: 103.384 | I38: 165.5 | J38: 19.48 | K38: 57330 | M38: =(B38-B37)/B37 -> -0.0080476538 | N38: =(C38-C37)/C37 -> -0.04890228 | O38: =(D38-D37)/D37 -> -0.028987552 | P38: =(E38-E37)/E37 -> 0.010145513 | Q38: =(F38-F37)/F37 -> -0.0030789249 | R38: =(G38-G37)/G37 -> 0.0076399058 | S38: =(H38-H37)/H37 -> -0.021133162 | T38: =(I38-I37)/I37 -> -0.0069006901 | ... V38: =(K38-K37)/K37 -> -0.084609366 | AL38: 43830 | AM38: 0.14
A39: 44561 | B39: 453.169 | C39: 65.9817 | D39: 47.5226 | E39: 114.41 | F39: 131.504 | G39: 126.953 | H39: 113.421 | I39: 170.96 | J39: 20.78 | K39: 47019 | M39: =(B39-B38)/B38 -> 0.046253478 | N39: =(C39-C38)/C38 -> 0.05198905 | O39: =(D39-D38)/D38 -> 0.015379422 | P39: =(E39-E38)/E38 -> -0.0059775148 | Q39: =(F39-F38)/F38 -> -0.0021095446 | R39: =(G39-G38)/G38 -> 0.002661591 | S39: =(H39-H38)/H38 -> 0.097084655 | T39: =(I39-I38)/I38 -> 0.032990937 | ... V39: =(K39-K38)/K38 -> -0.17985348 | X39: Covariances of yearly returns | Y39: SPY | Z39: VGK | AA39: VWO | AB39: IEF | AC39: LQD | AD39: TIP | AE39: VNQ | AF39: GLD | AG39: DBC | AH39: BTC | AL39: 43861 | AM39: 0.13
A40: 44592 | B40: 429.269 | C40: 63.6221 | D40: 47.725 | E40: 112 | F40: 126.78 | G40: 124.339 | H40: 103.866 | I40: 168.09 | J40: 22.42 | K40: 38438 | M40: =(B40-B39)/B39 -> -0.052739706 | N40: =(C40-C39)/C39 -> -0.035761431 | O40: =(D40-D39)/D39 -> 0.0042590262 | P40: =(E40-E39)/E39 -> -0.021064592 | Q40: =(F40-F39)/F39 -> -0.035922862 | R40: =(G40-G39)/G39 -> -0.020590297 | S40: =(H40-H39)/H39 -> -0.084243659 | T40: =(I40-I39)/I39 -> -0.016787553 | ... V40: =(K40-K39)/K39 -> -0.18250069 | X40: SPY | Y40: {=12*Y11:AH20} -> 0.027245392 | Z40: 0.024920526 | AA40: 0.018200738 | AB40: 0.0029586092 | AC40: 0.010417547 | AD40: 0.005875484 | AE40: 0.025534082 | AF40: 0.0037832892 | AG40: 0.011722863 | AH40: 0.052600708 | AL40: 43890 | AM40: 0.12
A41: 44620 | B41: 416.598 | C41: 60.2575 | D41: 45.9471 | E41: 111.551 | F41: 123.836 | G41: 124.963 | H41: 100.248 | I41: 178.38 | J41: 23.87 | K41: 43107 | M41: =(B41-B40)/B40 -> -0.029517622 | N41: =(C41-C40)/C40 -> -0.052884139 | O41: =(D41-D40)/D40 -> -0.037253012 | P41: =(E41-E40)/E40 -> -0.0040089286 | Q41: =(F41-F40)/F40 -> -0.023221328 | R41: =(G41-G40)/G40 -> 0.005018538 | S41: =(H41-H40)/H40 -> -0.034833343 | T41: =(I41-I40)/I40 -> 0.061217205 | ... V41: =(K41-K40)/K40 -> 0.12146834 | X41: VGK | Y41: 0.024920526 | Z41: 0.032724373 | AA41: 0.02234138 | AB41: 0.0038442389 | AC41: 0.011761862 | AD41: 0.0062484226 | AE41: 0.027011909 | AF41: 0.0074009737 | AG41: 0.015078434 | AH41: 0.041839951 | AL41: 43921 | AM41: 0.12
...

Sheet Efficient Frontier & Specific 
A1: Efficient Frontier (10 assets)
A3: Asset | B3: Expected return | C3: Volatility | E3: Correlations | F3: SPY | G3: VGK | H3: VWO | I3: IEF | J3: LQD | K3: TIP | L3: VNQ | M3: GLD | N3: DBC | O3: BTC | Q3: Covariances of monthly returns | R3: SPY | S3: VGK | T3: VWO | U3: IEF | V3: LQD | W3: TIP | X3: VNQ | Y3: GLD | Z3: DBC | AA3: BTC | AC3: Sylvester's criterion
A4: =Prices!Y$3 -> SPY | B4: =Prices!Y4 -> 0.013353829 | C4: =Prices!Y6 -> 0.047649233 | E4: SPY | F4: =Prices!Y26 -> 1 | G4: =Prices!Z26 -> 0.83459353 | H4: =Prices!AA26 -> 0.68918815 | I4: =Prices!AB26 -> 0.24578786 | J4: =Prices!AC26 -> 0.66292545 | K4: =Prices!AD26 -> 0.58699971 | L4: =Prices!AE26 -> 0.81607365 | M4: =Prices!AF26 -> 0.15773993 | ... O4: =Prices!AH26 -> 0.46096585 | Q4: SPY | R4: =Prices!Y11 -> 0.0022704494 | S4: =Prices!Z11 -> 0.0020767105 | T4: =Prices!AA11 -> 0.0015167281 | U4: =Prices!AB11 -> 0.00024655077 | V4: =Prices!AC11 -> 0.0008681289 | W4: =Prices!AD11 -> 0.00048962367 | X4: =Prices!AE11 -> 0.0021278402 | Y4: =Prices!AF11 -> 0.0003152741 | ... AA4: =Prices!AH11 -> 0.0043833924 | AC4: 0.0022704494
A5: =Prices!Z$3 -> VGK | B5: =Prices!Z4 -> 0.0084964115 | C5: =Prices!Z6 -> 0.052220983 | E5: VGK | G5: =Prices!Z27 -> 1 | H5: =Prices!AA27 -> 0.77191535 | I5: =Prices!AB27 -> 0.29140302 | J5: =Prices!AC27 -> 0.6829457 | K5: =Prices!AD27 -> 0.56960724 | L5: =Prices!AE27 -> 0.78772612 | M5: =Prices!AF27 -> 0.28156056 | N5: =Prices!AG27 -> 0.48797064 | O5: =Prices!AH27 -> 0.33456399 | Q5: VGK | R5: =Prices!Y12 -> 0.0020767105 | S5: =Prices!Z12 -> 0.002727031 | T5: =Prices!AA12 -> 0.0018617817 | U5: =Prices!AB12 -> 0.00032035324 | V5: =Prices!AC12 -> 0.00098015515 | W5: =Prices!AD12 -> 0.00052070188 | X5: =Prices!AE12 -> 0.0022509924 | Y5: =Prices!AF12 -> 0.0006167478 | ... AA5: =Prices!AH12 -> 0.0034866626 | AD5: 1.8788593e-06
A6: =Prices!AA$3 -> VWO | B6: =Prices!AA4 -> 0.0054307927 | C6: =Prices!AA6 -> 0.046186392 | E6: VWO | H6: =Prices!AA28 -> 1 | I6: =Prices!AB28 -> 0.21723646 | J6: =Prices!AC28 -> 0.64189323 | K6: =Prices!AD28 -> 0.44931846 | L6: =Prices!AE28 -> 0.61941506 | M6: =Prices!AF28 -> 0.34539843 | N6: =Prices!AG28 -> 0.49469495 | O6: =Prices!AH28 -> 0.25634914 | Q6: VWO | R6: =Prices!Y13 -> 0.0015167281 | S6: =Prices!Z13 -> 0.0018617817 | T6: =Prices!AA13 -> 0.0021331828 | U6: =Prices!AB13 -> 0.00021122084 | V6: =Prices!AC13 -> 0.00081478014 | W6: =Prices!AD13 -> 0.00036327617 | X6: =Prices!AE13 -> 0.0015654872 | Y6: =Prices!AF13 -> 0.00066915255 | ... AA6: =Prices!AH13 -> 0.0023628252 | AE6: 1.5931104e-09
A7: =Prices!AB$3 -> IEF | B7: =Prices!AB4 -> -0.00033629338 | C7: =Prices!AB6 -> 0.021051838 | E7: IEF | I7: =Prices!AB29 -> 1 | J7: =Prices!AC29 -> 0.78331896 | K7: =Prices!AD29 -> 0.77027045 | L7: =Prices!AE29 -> 0.39468054 | M7: =Prices!AF29 -> 0.3675722 | N7: =Prices!AG29 -> -0.2883916 | O7: =Prices!AH29 -> 0.11841452 | Q7: IEF | R7: =Prices!Y14 -> 0.00024655077 | S7: =Prices!Z14 -> 0.00032035324 | T7: =Prices!AA14 -> 0.00021122084 | U7: =Prices!AB14 -> 0.00044317989 | V7: =Prices!AC14 -> 0.00045320247 | W7: =Prices!AD14 -> 0.00028385848 | X7: =Prices!AE14 -> 0.00045466286 | Y7: =Prices!AF14 -> 0.00032458125 | ... AA7: =Prices!AH14 -> 0.00049748579 | AF7: 6.459494e-13
A8: =Prices!AC$3 -> LQD | B8: =Prices!AC4 -> 0.00051088612 | C8: =Prices!AC6 -> 0.027482967 | E8: LQD | J8: =Prices!AC30 -> 1 | K8: =Prices!AD30 -> 0.82397669 | L8: =Prices!AE30 -> 0.73173725 | M8: =Prices!AF30 -> 0.38027928 | N8: =Prices!AG30 -> 0.083179825 | O8: =Prices!AH30 -> 0.31226977 | Q8: LQD | R8: =Prices!Y15 -> 0.0008681289 | S8: =Prices!Z15 -> 0.00098015515 | T8: =Prices!AA15 -> 0.00081478014 | U8: =Prices!AB15 -> 0.00045320247 | V8: =Prices!AC15 -> 0.00075531345 | W8: =Prices!AD15 -> 0.00039641232 | X8: =Prices!AE15 -> 0.0011004556 | Y8: =Prices!AF15 -> 0.00043838635 | ... AA8: =Prices!AH15 -> 0.0017126919 | AG8: 5.1080238e-17
A9: =Prices!AD$3 -> TIP | B9: =Prices!AD4 -> 0.00079045933 | C9: =Prices!AD6 -> 0.017505262 | E9: TIP | K9: =Prices!AD31 -> 1 | L9: =Prices!AE31 -> 0.66911403 | M9: =Prices!AF31 -> 0.41945981 | N9: =Prices!AG31 -> 0.084887187 | O9: =Prices!AH31 -> 0.34613304 | Q9: TIP | R9: =Prices!Y16 -> 0.00048962367 | S9: =Prices!Z16 -> 0.00052070188 | T9: =Prices!AA16 -> 0.00036327617 | U9: =Prices!AB16 -> 0.00028385848 | V9: =Prices!AC16 -> 0.00039641232 | W9: =Prices!AD16 -> 0.00030643419 | X9: =Prices!AE16 -> 0.00064094753 | Y9: =Prices!AF16 -> 0.00030799929 | ... AA9: =Prices!AH16 -> 0.0012091978 | AH9: 3.6643133e-21
A10: =Prices!AE$3 -> VNQ | B10: =Prices!AE4 -> 0.0038919991 | C10: =Prices!AE6 -> 0.054720964 | E10: VNQ | L10: =Prices!AE32 -> 1 | M10: =Prices!AF32 -> 0.21561573 | N10: =Prices!AG32 -> 0.35588309 | O10: =Prices!AH32 -> 0.39827182 | Q10: VNQ | R10: =Prices!Y17 -> 0.0021278402 | S10: =Prices!Z17 -> 0.0022509924 | T10: =Prices!AA17 -> 0.0015654872 | U10: =Prices!AB17 -> 0.00045466286 | V10: =Prices!AC17 -> 0.0011004556 | W10: =Prices!AD17 -> 0.00064094753 | X10: =Prices!AE17 -> 0.0029943839 | Y10: =Prices!AF17 -> 0.00049490851 | ... AA10: =Prices!AH17 -> 0.0043492964 | AI10: 2.6255843e-24
A11: =Prices!AF$3 -> GLD | B11: =Prices!AF4 -> 0.01496557 | C11: =Prices!AF6 -> 0.041946019 | E11: GLD | M11: =Prices!AF33 -> 1 | N11: =Prices!AG33 -> 0.035311692 | O11: =Prices!AH33 -> 0.13211006 | Q11: GLD | R11: =Prices!Y18 -> 0.0003152741 | S11: =Prices!Z18 -> 0.0006167478 | T11: =Prices!AA18 -> 0.00066915255 | U11: =Prices!AB18 -> 0.00032458125 | V11: =Prices!AC18 -> 0.00043838635 | W11: =Prices!AD18 -> 0.00030799929 | X11: =Prices!AE18 -> 0.00049490851 | Y11: =Prices!AF18 -> 0.0017594685 | ... AA11: =Prices!AH18 -> 0.001105891 | AJ11: 3.2937397e-27
A12: =Prices!AG$3 -> DBC | B12: =Prices!AG4 -> 0.0060828471 | C12: =Prices!AG6 -> 0.049310143 | E12: DBC | N12: =Prices!AG34 -> 1 | O12: =Prices!AH34 -> 0.10625791 | Q12: DBC | R12: =Prices!Y19 -> 0.00097690527 | S12: =Prices!Z19 -> 0.0012565362 | T12: =Prices!AA19 -> 0.0011266468 | U12: =Prices!AB19 -> -0.00029937042 | V12: =Prices!AC19 -> 0.00011272438 | W12: =Prices!AD19 -> 7.3273513e-05 | X12: =Prices!AE19 -> 0.00096027881 | Y12: =Prices!AF19 -> 7.3037439e-05 | ... AA12: =Prices!AH19 -> 0.0010456425 | AK12: 3.886177e-30
A13: =Prices!AH$3 -> BTC | B13: =Prices!AH4 -> 0.057898273 | C13: =Prices!AG6 -> 0.049310143 | E13: BTC | O13: =Prices!AH35 -> 1 | Q13: BTC | R13: =Prices!Y20 -> 0.0043833924 | S13: =Prices!Z20 -> 0.0034866626 | T13: =Prices!AA20 -> 0.0023628252 | U13: =Prices!AB20 -> 0.00049748579 | V13: =Prices!AC20 -> 0.0017126919 | W13: =Prices!AD20 -> 0.0012091978 | X13: =Prices!AE20 -> 0.0043492964 | Y13: =Prices!AF20 -> 0.001105891 | ... AA13: =Prices!AH20 -> 0.03982643 | AL13: 1.1358429e-31
A14: Fama/French 3 Factors (Monthly) | B14: =Prices!AN27/100 -> 2.1049383e-05
A20: COMPUTATIONS using solver
A21: Sum of weights | B21: w1 | C21: w2 | D21: w3 | E21: w4 | F21: w5 | G21: w6 | H21: w7 | I21: w8 | J21: w9 | K21: w10 | L21: variance | M21: volatility | N21: Expected return | O21: Target Expected return | P21: Sharpe ratio
A22: =SUM(B22:K22) -> 1 | B22: 0.32515559 | C22: -0.11020513 | D22: 0.035179565 | E22: 0.82482255 | F22: -0.58849174 | G22: 0.37062519 | H22: -0.17416014 | I22: 0.12364038 | J22: 0.18688846 | K22: 0.0065453069 | L22: {=MMULT(MMULT(B22:K22,R4:AA13),TRANSPOSE(B22:K22))} -> 0.00023482796 | M22: =SQRT(L22) -> 0.015324097 | N22: {=MMULT(B22:K22,B4:B13)} -> 0.006 | O22: 0.006 | P22: =(N22-B14)/M22 -> 0.39016658
A25: PORTFOLIOS
A26: Sum of weights
A27: 0.99999996 | B27: -0.13479043 | C27: -0.071197516 | D27: 0.10762598 | E27: 0.24976097 | F27: -0.11923894 | G27: 1.0800692 | H27: -0.073792211 | I27: -0.15701482 | J27: 0.13735054 | K27: -0.018772748 | L27: 0.00023599389 | M27: 0.015362093 | N27: -0.004
A28: 1 | B28: 0.049188337 | C28: -0.086800884 | D28: 0.078647313 | E28: 0.47978568 | F28: -0.3069397 | G28: 0.79629114 | H28: -0.11393934 | I28: -0.044752713 | J28: 0.15716572 | K28: -0.0086455608 | L28: 0.00018204114 | M28: 0.013492262 | N28: 3.838738e-11
A29: 1.000001 | B29: 0.096395872 | C29: -0.090804633 | D29: 0.071220206 | E29: 0.5388064 | F29: -0.35510273 | G29: 0.72347819 | H29: -0.12424504 | I29: -0.015946034 | J29: 0.16224597 | K29: -0.0060471951 | L29: 0.00017969478 | M29: 0.013405028 | N29: 0.0010263809 | O29: GLOBAL MINIMUM VARIANCE PORTFOLIO
A30: 0.99999975 | B30: 0.18716397 | C30: -0.098499011 | D30: 0.056915462 | E30: 0.65229813 | F30: -0.44771203 | G30: 0.58346715 | H30: -0.14405012 | I30: 0.039440994 | J30: 0.17202523 | K30: -0.0010500189 | L30: 0.00018837618 | M30: 0.01372502 | N30: 0.0029999002
A31: 1 | B31: 0.32515559 | C31: -0.11020513 | D31: 0.035179565 | E31: 0.82482255 | F31: -0.58849174 | G31: 0.37062519 | H31: -0.17416014 | I31: 0.12364038 | J31: 0.18688846 | K31: 0.0065453069 | L31: 0.00023482796 | M31: 0.015324097 | N31: 0.006
A32: 1 | B32: 0.6011231 | C32: -0.13360982 | D32: -0.00828805 | E32: 1.1698576 | F32: -0.87004341 | G32: -0.055039394 | H32: -0.23438054 | I32: 0.29203362 | J32: 0.21661076 | K32: 0.021736115 | L32: 0.00044807392 | M32: 0.021167757 | N32: 0.012
A33: 1 | B33: 0.87709041 | C33: -0.15701483 | D33: -0.051754604 | E33: 1.5148967 | F33: -1.1515976 | G33: -0.48070624 | H33: -0.29460064 | I33: 0.46042668 | J33: 0.24633319 | K33: 0.03692701 | L33: 0.00082177907 | M33: 0.028666689 | N33: 0.018
A34: 1 | B34: 1.1530591 | C34: -0.18041984 | D34: -0.095223919 | E34: 1.859931 | F34: -1.4331468 | G34: -0.90637126 | H34: -0.35482194 | I34: 0.62882002 | J34: 0.27605596 | K34: 0.052117729 | L34: 0.0013559434 | M34: 0.036823136 | N34: 0.024
A35: 1.0000001 | B35: 3.3895933 | C35: -0.4952663 | D35: -0.010879785 | E35: 5.0230087 | F35: -4.3385477 | G35: -4.3422729 | H35: -0.78635076 | I35: 1.9514985 | J35: 0.42649033 | K35: 0.18272668 | L35: 0.0118298 | M35: 0.10876489 | N35: 0.072977525 | O35: HIGHEST SHARPE RATIO = TANGENT PORTFOLIO
A36: 1.0000003 | B36: 3.7287533 | C36: -0.39886006 | D36: -0.5009231 | E36: 5.080276 | F36: -4.0609613 | G36: -4.8792616 | H36: -0.91687955 | I36: 2.2004892 | J36: 0.55346845 | K36: 0.19389905 | L36: 0.014079174 | M36: 0.1186557 | N36: 0.08
A37: 1.0000001 | B37: 4.6486448 | C37: -0.47687445 | D37: -0.64581373 | E37: 6.230413 | F37: -4.9994773 | G37: -6.2981566 | H37: -1.117614 | I37: 2.7617985 | J37: 0.6525445 | K37: 0.24453539 | L37: 0.022010657 | M37: 0.14835989 | N37: 0.1
M39: Capital Allocation Line
L40: Risk free asset | M40: 0 | N40: =B14 -> 2.1049383e-05
E41: Optimal portfolio for a certain investor | L41: Tangent portfolio | M41: =M35 -> 0.10876489 | N41: =N35 -> 0.072977525
E43: Risk aversion | F43: Weight in the tangent portfolio | G43: expected return | H43: Volatility | L43: alpha
E44: =2*52 -> 104 | F44: =($N$35-$B$14)/(E44*($M$35^2)) -> 0.059299781 | G44: =$B$14 + F44*($N$35-$B$14) -> 0.0043473524 | H44: =F44*$M$35 -> 0.0064497339 | L44: 0 | M44: =$M$35*L44 -> 0 | N44: =$B$14+L44*($N$35-$B$14) -> 2.1049383e-05
E45: =3*52 -> 156 | F45: =($N$35-$B$14)/(E45*($M$35^2)) -> 0.039533187 | G45: =$B$14 + F45*($N$35-$B$14) -> 0.0029052514 | H45: =F45*$M$35 -> 0.0042998226 | L45: 0.25 | M45: =$M$35*L45 -> 0.027191222 | N45: =$B$14+L45*($N$35-$B$14) -> 0.018260168
E46: =4*52 -> 208 | F46: =($N$35-$B$14)/(E46*($M$35^2)) -> 0.02964989 | G46: =$B$14 + F46*($N$35-$B$14) -> 0.0021842009 | H46: =F46*$M$35 -> 0.0032248669 | L46: 0.5 | M46: =$M$35*L46 -> 0.054382443 | N46: =$B$14+L46*($N$35-$B$14) -> 0.036499287
E47: =5*52 -> 260 | F47: =($N$35-$B$14)/(E47*($M$35^2)) -> 0.023719912 | G47: =$B$14 + F47*($N$35-$B$14) -> 0.0017515706 | H47: =F47*$M$35 -> 0.0025798936 | L47: 0.75 | M47: =$M$35*L47 -> 0.081573665 | N47: =$B$14+L47*($N$35-$B$14) -> 0.054738406
L48: 1 | M48: =$M$35*L48 -> 0.10876489 | N48: =$B$14+L48*($N$35-$B$14) -> 0.072977525
L49: 1.25 | M49: =$M$35*L49 -> 0.13595611 | N49: =$B$14+L49*($N$35-$B$14) -> 0.091216644
L50: 1.5 | M50: =$M$35*L50 -> 0.16314733 | N50: =$B$14+L50*($N$35-$B$14) -> 0.10945576
...

Sheet Explanations
A1: Explanations
A3: 1. Asset Selection and Economic Rationale
A4: The portfolio includes a diversified set of assets spanning equities, fixed income, real assets, commodities, and alternative investments. The objective is to capture different sources of return while benefiting
A5: from imperfect correlations across asset classes.
A7: SPY – US Equity Market
A8: SPY represents the US equity market and serves as a benchmark for developed market equities. It offers strong long-term growth potential but exhibits relatively high volatility, reflecting sensitivity to economic cycles,
A9: monetary policy, and corporate earnings. SPY acts as a core growth asset in the portfolio.
A11: VGK – European Equity Market
A12: VGK provides exposure to developed European equities. Compared to SPY, VGK displays slightly lower expected returns and different cyclical dynamics, influenced by European monetary policy and regional economic
A13: conditions. Including VGK enhances geographical diversification and reduces dependence on a single equity market.
A15: VWO – Emerging Market Equities
A16: VWO captures exposure to emerging market economies. While expected returns are lower in the sample period, VWO exhibits different growth drivers and correlation patterns compared to developed markets. This
... A82: This structure reflects realistic investor objectives and enables meaningful construction of efficient portfolios under different constraints and risk preferences.

Sheet No short sales
A2: Asset | B2: Expected return | C2: Volatility | E2: {=Prices!X25:AH35} -> Correlations | F2: SPY | G2: VGK | H2: VWO | I2: IEF | J2: LQD | K2: TIP | L2: VNQ | M2: GLD | N2: DBC | O2: BTC | Q2: {=Prices!X10:AH20} -> Covariances of monthly returns | R2: SPY | S2: VGK | T2: VWO | U2: IEF | V2: LQD | W2: TIP | X2: VNQ | Y2: GLD | Z2: DBC | AA2: BTC
A3: =Prices!Y$3 -> SPY | B3: =Prices!Y4 -> 0.013353829 | C3: =Prices!Y6 -> 0.047649233 | E3: SPY | F3: 1 | G3: 0.83459353 | H3: 0.68918815 | I3: 0.24578786 | J3: 0.66292545 | K3: 0.58699971 | L3: 0.81607365 | M3: 0.15773993 | N3: 0.41577683 | O3: 0.46096585 | Q3: SPY | R3: 0.0022704494 | S3: 0.0020767105 | T3: 0.0015167281 | U3: 0.00024655077 | V3: 0.0008681289 | W3: 0.00048962367 | X3: 0.0021278402 | Y3: 0.0003152741 | Z3: 0.00097690527 | AA3: 0.0043833924
A4: =Prices!Z$3 -> VGK | B4: =Prices!Z4 -> 0.0084964115 | C4: =Prices!Z6 -> 0.052220983 | E4: VGK | F4: 0 | G4: 1 | H4: 0.77191535 | I4: 0.29140302 | J4: 0.6829457 | K4: 0.56960724 | L4: 0.78772612 | M4: 0.28156056 | N4: 0.48797064 | O4: 0.33456399 | Q4: VGK | R4: 0.0020767105 | S4: 0.002727031 | T4: 0.0018617817 | U4: 0.00032035324 | V4: 0.00098015515 | W4: 0.00052070188 | X4: 0.0022509924 | Y4: 0.0006167478 | Z4: 0.0012565362 | AA4: 0.0034866626
A5: =Prices!AA$3 -> VWO | B5: =Prices!AA4 -> 0.0054307927 | C5: =Prices!AA6 -> 0.046186392 | E5: VWO | F5: 0 | G5: 0 | H5: 1 | I5: 0.21723646 | J5: 0.64189323 | K5: 0.44931846 | L5: 0.61941506 | M5: 0.34539843 | N5: 0.49469495 | O5: 0.25634914 | Q5: VWO | R5: 0.0015167281 | S5: 0.0018617817 | T5: 0.0021331828 | U5: 0.00021122084 | V5: 0.00081478014 | W5: 0.00036327617 | X5: 0.0015654872 | Y5: 0.00066915255 | Z5: 0.0011266468 | AA5: 0.0023628252
A6: =Prices!AB$3 -> IEF | B6: =Prices!AB4 -> -0.00033629338 | C6: =Prices!AB6 -> 0.021051838 | E6: IEF | F6: 0 | G6: 0 | H6: 0 | I6: 1 | J6: 0.78331896 | K6: 0.77027045 | L6: 0.39468054 | M6: 0.3675722 | N6: -0.2883916 | O6: 0.11841452 | Q6: IEF | R6: 0.00024655077 | S6: 0.00032035324 | T6: 0.00021122084 | U6: 0.00044317989 | V6: 0.00045320247 | W6: 0.00028385848 | X6: 0.00045466286 | Y6: 0.00032458125 | Z6: -0.00029937042 | AA6: 0.00049748579
A7: =Prices!AC$3 -> LQD | B7: =Prices!AC4 -> 0.00051088612 | C7: =Prices!AC6 -> 0.027482967 | E7: LQD | F7: 0 | G7: 0 | H7: 0 | I7: 0 | J7: 1 | K7: 0.82397669 | L7: 0.73173725 | M7: 0.38027928 | N7: 0.083179825 | O7: 0.31226977 | Q7: LQD | R7: 0.0008681289 | S7: 0.00098015515 | T7: 0.00081478014 | U7: 0.00045320247 | V7: 0.00075531345 | W7: 0.00039641232 | X7: 0.0011004556 | Y7: 0.00043838635 | Z7: 0.00011272438 | AA7: 0.0017126919
A8: =Prices!AD$3 -> TIP | B8: =Prices!AD4 -> 0.00079045933 | C8: =Prices!AD6 -> 0.017505262 | E8: TIP | F8: 0 | G8: 0 | H8: 0 | I8: 0 | J8: 0 | K8: 1 | L8: 0.66911403 | M8: 0.41945981 | N8: 0.084887187 | O8: 0.34613304 | Q8: TIP | R8: 0.00048962367 | S8: 0.00052070188 | T8: 0.00036327617 | U8: 0.00028385848 | V8: 0.00039641232 | W8: 0.00030643419 | X8: 0.00064094753 | Y8: 0.00030799929 | Z8: 7.3273513e-05 | AA8: 0.0012091978
A9: =Prices!AE$3 -> VNQ | B9: =Prices!AE4 -> 0.0038919991 | C9: =Prices!AE6 -> 0.054720964 | E9: VNQ | F9: 0 | G9: 0 | H9: 0 | I9: 0 | J9: 0 | K9: 0 | L9: 1 | M9: 0.21561573 | N9: 0.35588309 | O9: 0.39827182 | Q9: VNQ | R9: 0.0021278402 | S9: 0.0022509924 | T9: 0.0015654872 | U9: 0.00045466286 | V9: 0.0011004556 | W9: 0.00064094753 | X9: 0.0029943839 | Y9: 0.00049490851 | Z9: 0.00096027881 | AA9: 0.0043492964
A10: =Prices!AF$3 -> GLD | B10: =Prices!AF4 -> 0.01496557 | C10: =Prices!AF6 -> 0.041946019 | E10: GLD | F10: 0 | G10: 0 | H10: 0 | I10: 0 | J10: 0 | K10: 0 | L10: 0 | M10: 1 | N10: 0.035311692 | O10: 0.13211006 | Q10: GLD | R10: 0.0003152741 | S10: 0.0006167478 | T10: 0.00066915255 | U10: 0.00032458125 | V10: 0.00043838635 | W10: 0.00030799929 | X10: 0.00049490851 | Y10: 0.0017594685 | Z10: 7.3037439e-05 | AA10: 0.001105891
A11: =Prices!AG$3 -> DBC | B11: =Prices!AG4 -> 0.0060828471 | C11: =Prices!AG6 -> 0.049310143 | E11: DBC | F11: 0 | G11: 0 | H11: 0 | I11: 0 | J11: 0 | K11: 0 | L11: 0 | M11: 0 | N11: 1 | O11: 0.10625791 | Q11: DBC | R11: 0.00097690527 | S11: 0.0012565362 | T11: 0.0011266468 | U11: -0.00029937042 | V11: 0.00011272438 | W11: 7.3273513e-05 | X11: 0.00096027881 | Y11: 7.3037439e-05 | Z11: 0.0024314902 | AA11: 0.0010456425
A12: =Prices!AH$3 -> BTC | B12: =Prices!AH4 -> 0.057898273 | C12: =Prices!AG6 -> 0.049310143 | E12: BTC | F12: 0 | G12: 0 | H12: 0 | I12: 0 | J12: 0 | K12: 0 | L12: 0 | M12: 0 | N12: 0 | O12: 1 | Q12: BTC | R12: 0.0043833924 | S12: 0.0034866626 | T12: 0.0023628252 | U12: 0.00049748579 | V12: 0.0017126919 | W12: 0.0012091978 | X12: 0.0043492964 | Y12: 0.001105891 | Z12: 0.0010456425 | AA12: 0.03982643
A13: ='Efficient Frontier & Specific '!$A$14 -> Fama/French 3 Factors (Monthly) | B13: ='Efficient Frontier & Specific '!$B$14 -> 2.1049383e-05
U14: With short sales
A20: COMPUTATIONS using solver
A21: Sum of weights | B21: w1 | C21: w2 | D21: w3 | E21: w4 | F21: w5 | G21: w6 | H21: w7 | I21: w8 | J21: w9 | K21: w10 | L21: variance | M21: volatility | N21: Expected return | O21: Target Expected return | P21: Sharpe ratio
A22: =SUM(B22:K22) -> 1 | B22: 0 | C22: 0 | D22: 0 | E22: 0.96778913 | F22: 0 | G22: 0.032210881 | H22: 0 | I22: 0 | J22: 0 | K22: 0 | L22: {=MMULT(MMULT(B22:K22,R3:AA12),TRANSPOSE(B22:K22))} -> 0.00043310486 | M22: =SQRT(L22) -> 0.020811171 | N22: {=MMULT(B22:K22,B3:B12)} -> -0.00029999968 | O22: -0.0003 | P22: =(N22-B13)/M22 -> -0.015426766
A25: PORTFOLIOS with no short sales allowed
A26: Sum of weights
A27: 1 | B27: 0 | C27: 0 | D27: 0 | E27: 0.96778913 | F27: 0 | G27: 0.032210881 | H27: 0 | I27: 0 | J27: 0 | K27: 0 | L27: 0.00043310486 | M27: 0.020811171 | N27: -0.00029999968
A28: 1 | B28: 0 | C28: 0 | D28: 0 | E28: 0.4273719 | F28: 0 | G28: 0.4420475 | H28: 0 | I28: 0 | J28: 0.1305806 | K28: 0 | L28: 0.00026458232 | M28: 0.016265987 | N28: 0.0010000001
A29: 1 | B29: 0 | C29: 0 | D29: 0 | E29: 0.40171067 | F29: 0 | G29: 0.45404701 | H29: 0 | I29: 0 | J29: 0.14424236 | K29: 0 | L29: 0.00026373345 | M29: 0.016239872 | N29: 0.0011012173 | O29: GLOBAL MINIMUM VARIANCE PORTFOLIO
A30: 1 | B30: 0.089169407 | C30: 0 | D30: 0 | E30: 0.40595257 | F30: 0 | G30: 0 | H30: 0 | I30: 0.29982821 | J30: 0.18167107 | K30: 0.023378743 | L30: 0.00051255233 | M30: 0.022639619 | N30: 0.0080000001 | U30: Without short sales
A31: 0.99999999 | B31: 0.23002046 | C31: 0 | D31: 0 | E31: 0 | F31: 0 | G31: 0 | H31: 0 | I31: 0.62542734 | J31: 0.065990321 | K31: 0.078561867 | L31: 0.0014690943 | M31: 0.038328765 | N31: 0.017381536 | O31: HIGHEST SHARPE RATIO = TANGENT PORTFOLIO
A32: 1 | B32: 0 | C32: 0 | D32: 0 | E32: 0 | F32: 0 | G32: 0 | H32: 0 | I32: 0.69639815 | J32: 0 | K32: 0.30360185 | L32: 0.0049918868 | M32: 0.070653286 | N32: 0.028000018
A33: 0.99999998 | B33: 0 | C33: 0 | D33: 0 | E33: 0 | F33: 0 | G33: 0 | H33: 0 | I33: 0.46347522 | J33: 0 | K33: 0.53652476 | L33: 0.012392334 | M33: 0.11132086 | N33: 0.038000028
A34: 0.99999998 | B34: 0 | C34: 0 | D34: 0 | E34: 0 | F34: 0 | G34: 0 | H34: 0 | I34: 0.23055231 | J34: 0 | K34: 0.76944767 | L34: 0.024065115 | M34: 0.15512935 | N34: 0.048000038
A35: 1 | B35: 0 | C35: 0 | D35: 0 | E35: 0 | F35: 0 | G35: 0 | H35: 0 | I35: 0.18396869 | J35: 0 | K35: 0.81603131 | L35: 0.026912293 | M35: 0.16404967 | N35: 0.05
M37: Capital Allocation Line
L38: Risk free asset | M38: 0 | N38: =B13 -> 2.1049383e-05
L39: Tangent portfolio | M39: =M31 -> 0.038328765 | N39: =N31 -> 0.017381536
L41: alpha
L42: 0 | M42: =$M$31*L42 -> 0 | N42: =$B$14+L42*($N$31-$B$14) -> 0
L43: 0.25 | M43: =$M$31*L43 -> 0.0095821914 | N43: =$B$14+L43*($N$31-$B$14) -> 0.004345384
L44: 0.5 | M44: =$M$31*L44 -> 0.019164383 | N44: =$B$14+L44*($N$31-$B$14) -> 0.008690768
L45: 0.75 | M45: =$M$31*L45 -> 0.028746574 | N45: =$B$14+L45*($N$31-$B$14) -> 0.013036152
L46: 1 | M46: =$M$31*L46 -> 0.038328765 | N46: =$B$14+L46*($N$31-$B$14) -> 0.017381536
L47: 1.25 | M47: =$M$31*L47 -> 0.047910957 | N47: =$B$14+L47*($N$31-$B$14) -> 0.02172692
L48: 1.5 | M48: =$M$31*L48 -> 0.057493148 | N48: =$B$14+L48*($N$31-$B$14) -> 0.026072304
A49: CONCLUSION | L49: 5.22 | M49: =$M$31*L49 -> 0.20007616 | N49: =$B$14+L49*($N$31-$B$14) -> 0.090731618
A50: Imposing a no-short-sales constraint modifies the shape of the efficient frontier. Compared to the unconstrained case, the constrained frontier is generally less efficient, as the restriction limits
...

Sheet Changing the data +2% Vol
A2: Asset | B2: Expected return | C2: Volatility | D2: Volatility +2% | F2: {='Efficient Frontier & Specific '!E3:O13} -> Correlations | G2: SPY | H2: VGK | I2: VWO | J2: IEF | K2: LQD | L2: TIP | M2: VNQ | N2: GLD | O2: DBC | P2: BTC | R2: {='Efficient Frontier & Specific '!Q3:AA13} -> Covariances of monthly returns | S2: SPY | T2: VGK | U2: VWO | V2: IEF | W2: LQD | X2: TIP | Y2: VNQ | Z2: GLD | AA2: DBC | AB2: BTC | AD2: NEW Covariances of monthly returns | AE2: SPY | AF2: VGK | AG2: VWO | AH2: IEF | AI2: LQD | AJ2: TIP | AK2: VNQ | AL2: GLD | AM2: DBC | AN2: BTC
A3: =Prices!Y$3 -> SPY | B3: =Prices!Y4 -> 0.013353829 | C3: =Prices!Y6 -> 0.047649233 | D3: =C3*1.02 -> 0.048602217 | F3: SPY | G3: 1 | H3: 0.83459353 | I3: 0.68918815 | J3: 0.24578786 | K3: 0.66292545 | L3: 0.58699971 | M3: 0.81607365 | N3: 0.15773993 | O3: 0.41577683 | P3: 0.46096585 | R3: SPY | S3: 0.0022704494 | T3: 0.0020767105 | U3: 0.0015167281 | V3: 0.00024655077 | W3: 0.0008681289 | X3: 0.00048962367 | Y3: 0.0021278402 | Z3: 0.0003152741 | AA3: 0.00097690527 | AB3: 0.0043833924 | AD3: SPY | AE3: {=INDEX($G$3:$P$12, ROWS($S$3:S3), COLUMNS($S$3:S3)) * INDEX($D$3:$D$12, ROWS($S$3:S3)) * INDEX($D$3:$D$12, COLUMNS($S$3:S3))} -> 0.0023621755 | AF3: {=INDEX($G$3:$P$12, ROWS($S$3:T3), COLUMNS($S$3:T3)) * INDEX($D$3:$D$12, ROWS($S$3:T3)) * INDEX($D$3:$D$12, COLUMNS($S$3:T3))} -> 0.0021606096 | AG3: {=INDEX($G$3:$P$12, ROWS($S$3:U3), COLUMNS($S$3:U3)) * INDEX($D$3:$D$12, ROWS($S$3:U3)) * INDEX($D$3:$D$12, COLUMNS($S$3:U3))} -> 0.001578004 | AH3: {=INDEX($G$3:$P$12, ROWS($S$3:V3), COLUMNS($S$3:V3)) * INDEX($D$3:$D$12, ROWS($S$3:V3)) * INDEX($D$3:$D$12, COLUMNS($S$3:V3))} -> 0.00025651142 | AI3: {=INDEX($G$3:$P$12, ROWS($S$3:W3), COLUMNS($S$3:W3)) * INDEX($D$3:$D$12, ROWS($S$3:W3)) * INDEX($D$3:$D$12, COLUMNS($S$3:W3))} -> 0.00090320131 | AJ3: {=INDEX($G$3:$P$12, ROWS($S$3:X3), COLUMNS($S$3:X3)) * INDEX($D$3:$D$12, ROWS($S$3:X3)) * INDEX($D$3:$D$12, COLUMNS($S$3:X3))} -> 0.00050940447 | AK3: {=INDEX($G$3:$P$12, ROWS($S$3:Y3), COLUMNS($S$3:Y3)) * INDEX($D$3:$D$12, ROWS($S$3:Y3)) * INDEX($D$3:$D$12, COLUMNS($S$3:Y3))} -> 0.0022138049 | AL3: {=INDEX($G$3:$P$12, ROWS($S$3:Z3), COLUMNS($S$3:Z3)) * INDEX($D$3:$D$12, ROWS($S$3:Z3)) * INDEX($D$3:$D$12, COLUMNS($S$3:Z3))} -> 0.00032801117 | ... AN3: {=INDEX($G$3:$P$12, ROWS($S$3:AB3), COLUMNS($S$3:AB3)) * INDEX($D$3:$D$12, ROWS($S$3:AB3)) * INDEX($D$3:$D$12, COLUMNS($S$3:AB3))} -> 0.0011268374
A4: =Prices!Z$3 -> VGK | B4: =Prices!Z4 -> 0.0084964115 | C4: =Prices!Z6 -> 0.052220983 | D4: =C4*1.02 -> 0.053265402 | F4: VGK | G4: 0 | H4: 1 | I4: 0.77191535 | J4: 0.29140302 | K4: 0.6829457 | L4: 0.56960724 | M4: 0.78772612 | N4: 0.28156056 | O4: 0.48797064 | P4: 0.33456399 | R4: VGK | S4: 0.0020767105 | T4: 0.002727031 | U4: 0.0018617817 | V4: 0.00032035324 | W4: 0.00098015515 | X4: 0.00052070188 | Y4: 0.0022509924 | Z4: 0.0006167478 | AA4: 0.0012565362 | AB4: 0.0034866626 | AD4: VGK | AE4: =AF$3 -> 0.0021606096 | AF4: {=INDEX($G$3:$P$12, ROWS($S$3:T4), COLUMNS($S$3:T4)) * INDEX($D$3:$D$12, ROWS($S$3:T4)) * INDEX($D$3:$D$12, COLUMNS($S$3:T4))} -> 0.0028372031 | AG4: {=INDEX($G$3:$P$12, ROWS($S$3:U4), COLUMNS($S$3:U4)) * INDEX($D$3:$D$12, ROWS($S$3:U4)) * INDEX($D$3:$D$12, COLUMNS($S$3:U4))} -> 0.0019369977 | AH4: {=INDEX($G$3:$P$12, ROWS($S$3:V4), COLUMNS($S$3:V4)) * INDEX($D$3:$D$12, ROWS($S$3:V4)) * INDEX($D$3:$D$12, COLUMNS($S$3:V4))} -> 0.00033329551 | AI4: {=INDEX($G$3:$P$12, ROWS($S$3:W4), COLUMNS($S$3:W4)) * INDEX($D$3:$D$12, ROWS($S$3:W4)) * INDEX($D$3:$D$12, COLUMNS($S$3:W4))} -> 0.0010197534 | AJ4: {=INDEX($G$3:$P$12, ROWS($S$3:X4), COLUMNS($S$3:X4)) * INDEX($D$3:$D$12, ROWS($S$3:X4)) * INDEX($D$3:$D$12, COLUMNS($S$3:X4))} -> 0.00054173824 | AK4: {=INDEX($G$3:$P$12, ROWS($S$3:Y4), COLUMNS($S$3:Y4)) * INDEX($D$3:$D$12, ROWS($S$3:Y4)) * INDEX($D$3:$D$12, COLUMNS($S$3:Y4))} -> 0.0023419325 | AL4: {=INDEX($G$3:$P$12, ROWS($S$3:Z4), COLUMNS($S$3:Z4)) * INDEX($D$3:$D$12, ROWS($S$3:Z4)) * INDEX($D$3:$D$12, COLUMNS($S$3:Z4))} -> 0.00064166442 | AM4: {=INDEX($G$3:$P$12, ROWS($S$3:AA4), COLUMNS($S$3:AA4)) * INDEX($D$3:$D$12, ROWS($S$3:AA4)) * INDEX($D$3:$D$12, COLUMNS($S$3:AA4))} -> 0.0013073002 | AN4: {=INDEX($G$3:$P$12, ROWS($S$3:AB4), COLUMNS($S$3:AB4)) * INDEX($D$3:$D$12, ROWS($S$3:AB4)) * INDEX($D$3:$D$12, COLUMNS($S$3:AB4))} -> 0.00089631536
A5: =Prices!AA$3 -> VWO | B5: =Prices!AA4 -> 0.0054307927 | C5: =Prices!AA6 -> 0.046186392 | D5: =C5*1.02 -> 0.047110119 | F5: VWO | G5: 0 | H5: 0 | I5: 1 | J5: 0.21723646 | K5: 0.64189323 | L5: 0.44931846 | M5: 0.61941506 | N5: 0.34539843 | O5: 0.49469495 | P5: 0.25634914 | R5: VWO | S5: 0.0015167281 | T5: 0.0018617817 | U5: 0.0021331828 | V5: 0.00021122084 | W5: 0.00081478014 | X5: 0.00036327617 | Y5: 0.0015654872 | Z5: 0.00066915255 | AA5: 0.0011266468 | AB5: 0.0023628252 | AD5: VWO | AE5: =AG3 -> 0.001578004 | AF5: =AG4 -> 0.0019369977 | AG5: {=INDEX($G$3:$P$12, ROWS($S$3:U5), COLUMNS($S$3:U5)) * INDEX($D$3:$D$12, ROWS($S$3:U5)) * INDEX($D$3:$D$12, COLUMNS($S$3:U5))} -> 0.0022193634 | AH5: {=INDEX($G$3:$P$12, ROWS($S$3:V5), COLUMNS($S$3:V5)) * INDEX($D$3:$D$12, ROWS($S$3:V5)) * INDEX($D$3:$D$12, COLUMNS($S$3:V5))} -> 0.00021975416 | AI5: {=INDEX($G$3:$P$12, ROWS($S$3:W5), COLUMNS($S$3:W5)) * INDEX($D$3:$D$12, ROWS($S$3:W5)) * INDEX($D$3:$D$12, COLUMNS($S$3:W5))} -> 0.00084769726 | AJ5: {=INDEX($G$3:$P$12, ROWS($S$3:X5), COLUMNS($S$3:X5)) * INDEX($D$3:$D$12, ROWS($S$3:X5)) * INDEX($D$3:$D$12, COLUMNS($S$3:X5))} -> 0.00037795253 | AK5: {=INDEX($G$3:$P$12, ROWS($S$3:Y5), COLUMNS($S$3:Y5)) * INDEX($D$3:$D$12, ROWS($S$3:Y5)) * INDEX($D$3:$D$12, COLUMNS($S$3:Y5))} -> 0.0016287329 | AL5: {=INDEX($G$3:$P$12, ROWS($S$3:Z5), COLUMNS($S$3:Z5)) * INDEX($D$3:$D$12, ROWS($S$3:Z5)) * INDEX($D$3:$D$12, COLUMNS($S$3:Z5))} -> 0.00069618631 | AM5: {=INDEX($G$3:$P$12, ROWS($S$3:AA5), COLUMNS($S$3:AA5)) * INDEX($D$3:$D$12, ROWS($S$3:AA5)) * INDEX($D$3:$D$12, COLUMNS($S$3:AA5))} -> 0.0011721633 | AN5: {=INDEX($G$3:$P$12, ROWS($S$3:AB5), COLUMNS($S$3:AB5)) * INDEX($D$3:$D$12, ROWS($S$3:AB5)) * INDEX($D$3:$D$12, COLUMNS($S$3:AB5))} -> 0.00060741079
A6: =Prices!AB$3 -> IEF | B6: =Prices!AB4 -> -0.00033629338 | C6: =Prices!AB6 -> 0.021051838 | D6: =C6*1.02 -> 0.021472875 | F6: IEF | G6: 0 | H6: 0 | I6: 0 | J6: 1 | K6: 0.78331896 | L6: 0.77027045 | M6: 0.39468054 | N6: 0.3675722 | O6: -0.2883916 | P6: 0.11841452 | R6: IEF | S6: 0.00024655077 | T6: 0.00032035324 | U6: 0.00021122084 | V6: 0.00044317989 | W6: 0.00045320247 | X6: 0.00028385848 | Y6: 0.00045466286 | Z6: 0.00032458125 | AA6: -0.00029937042 | AB6: 0.00049748579 | AD6: IEF | AE6: =AH3 -> 0.00025651142 | AF6: =AH4 -> 0.00033329551 | AG6: =AH5 -> 0.00021975416 | AH6: {=INDEX($G$3:$P$12, ROWS($S$3:V6), COLUMNS($S$3:V6)) * INDEX($D$3:$D$12, ROWS($S$3:V6)) * INDEX($D$3:$D$12, COLUMNS($S$3:V6))} -> 0.00046108436 | AI6: {=INDEX($G$3:$P$12, ROWS($S$3:W6), COLUMNS($S$3:W6)) * INDEX($D$3:$D$12, ROWS($S$3:W6)) * INDEX($D$3:$D$12, COLUMNS($S$3:W6))} -> 0.00047151185 | AJ6: {=INDEX($G$3:$P$12, ROWS($S$3:X6), COLUMNS($S$3:X6)) * INDEX($D$3:$D$12, ROWS($S$3:X6)) * INDEX($D$3:$D$12, COLUMNS($S$3:X6))} -> 0.00029532636 | AK6: {=INDEX($G$3:$P$12, ROWS($S$3:Y6), COLUMNS($S$3:Y6)) * INDEX($D$3:$D$12, ROWS($S$3:Y6)) * INDEX($D$3:$D$12, COLUMNS($S$3:Y6))} -> 0.00047303123 | AL6: {=INDEX($G$3:$P$12, ROWS($S$3:Z6), COLUMNS($S$3:Z6)) * INDEX($D$3:$D$12, ROWS($S$3:Z6)) * INDEX($D$3:$D$12, COLUMNS($S$3:Z6))} -> 0.00033769433 | AM6: {=INDEX($G$3:$P$12, ROWS($S$3:AA6), COLUMNS($S$3:AA6)) * INDEX($D$3:$D$12, ROWS($S$3:AA6)) * INDEX($D$3:$D$12, COLUMNS($S$3:AA6))} -> -0.00031146499 | AN6: {=INDEX($G$3:$P$12, ROWS($S$3:AB6), COLUMNS($S$3:AB6)) * INDEX($D$3:$D$12, ROWS($S$3:AB6)) * INDEX($D$3:$D$12, COLUMNS($S$3:AB6))} -> 0.00012788853
